Waar volgende keer mee verder:
Als ik een get doe op /get_all_bodyweight_stats dan krijg ik een db connection error. 
Maar als ik statistics.py the functie uitvoer dan gaat het wel goed. Vermoeden is dus er ergens iets mis gaat in routes.py en het inladen van bepaalde zaken
